<?xml version='1.0'?>
<sdf version='1.6'>
  <model name='lander'>
    <link name='base'>
      <inertial>
	<mass>21.544178</mass>
	<inertia>
	  <ixx>1.81006</ixx>
	  <ixy>0.0196695</ixy>
	  <ixz>0</ixz>
	  <iyy>2.83132</iyy>
	  <iyz>0.010958</iyz>
	  <izz>1.90705</izz>
	</inertia>
	<pose frame=''>0 0 0 0 -0 0</pose>
      </inertial>
      <self_collide>0</self_collide>
      <enable_wind>0</enable_wind>
      <kinematic>0</kinematic>
      <gravity>1</gravity>
      <pose frame=''>-0 -0 0.3 0 -0 0</pose>
      <visual name='base_fixed_joint_lump__leg_hinge_4_visual_10'>
	<geometry>
	  <mesh>
	    <scale>1 1 1</scale>
	    <uri>model://lander/meshes/leg_hinge_4.stl</uri>
	  </mesh>
	</geometry>
	<pose frame=''>-0.3125 -0.3125 0.015 0 0 -0.7854</pose>
	<material>
	  <shader type='pixel'>
	    <normal_map>__default__</normal_map>
	  </shader>
	  <script>
	    <name>ModelPreview_4::base::base_fixed_joint_lump__leg_hinge_4_visual_10_MATERIAL_</name>
	    <uri>__default__</uri>
	  </script>
	</material>
	<transparency>0</transparency>
	<cast_shadows>1</cast_shadows>
      </visual>
      <visual name='base_fixed_joint_lump__supports_top_visual_2'>
	<geometry>
	  <mesh>
	    <scale>1 1 1</scale>
	    <uri>model://lander/meshes/supports_top.stl</uri>
	  </mesh>
	</geometry>
	<pose frame=''>0 0 0.0175 0 -0 0</pose>
	<material>
	  <shader type='pixel'>
	    <normal_map>__default__</normal_map>
	  </shader>
	  <script>
	    <name>ModelPreview_4::base::base_fixed_joint_lump__supports_top_visual_2_MATERIAL_</name>
	    <uri>__default__</uri>
	  </script>
	</material>
	<transparency>0</transparency>
	<cast_shadows>1</cast_shadows>
      </visual>
      <visual name='base_fixed_joint_lump__supports_engine_visual_12'>
	<geometry>
	  <mesh>
	    <scale>1 1 1</scale>
	    <uri>model://lander/meshes/supports_engine.stl</uri>
	  </mesh>
	</geometry>
	<pose frame=''>0 0 -0.025 0 -0 0</pose>
	<material>
	  <shader type='pixel'>
	    <normal_map>__default__</normal_map>
	  </shader>
	  <script>
	    <name>ModelPreview_4::base::base_fixed_joint_lump__supports_engine_visual_12_MATERIAL_</name>
	    <uri>__default__</uri>
	  </script>
	</material>
	<transparency>0</transparency>
	<cast_shadows>1</cast_shadows>
      </visual>
      <visual name='base_fixed_joint_lump__leg_hinge_1_visual_4'>
	<geometry>
	  <mesh>
	    <scale>1 1 1</scale>
	    <uri>model://lander/meshes/leg_hinge_1.stl</uri>
	  </mesh>
	</geometry>
	<pose frame=''>-0.3125 0.3125 0.015 0 -0 0.7854</pose>
	<material>
	  <shader type='pixel'>
	    <normal_map>__default__</normal_map>
	  </shader>
	  <script>
	    <name>ModelPreview_4::base::base_fixed_joint_lump__leg_hinge_1_visual_4_MATERIAL_</name>
	    <uri>__default__</uri>
	  </script>
	</material>
	<transparency>0</transparency>
	<cast_shadows>1</cast_shadows>
      </visual>
      <visual name='base_fixed_joint_lump__thruster_1_visual_35'>
	<geometry>
	  <mesh>
	    <scale>1 1 1</scale>
	    <uri>model://lander/meshes/thruster_1.stl</uri>
	  </mesh>
	</geometry>
	<pose frame=''>-0.385 0 -0.056 0 -0 0</pose>
	<material>
	  <shader type='pixel'>
	    <normal_map>__default__</normal_map>
	  </shader>
	  <script>
	    <name>ModelPreview_4::base::base_fixed_joint_lump__thruster_1_visual_35_MATERIAL_</name>
	    <uri>__default__</uri>
	  </script>
	</material>
	<transparency>0</transparency>
	<cast_shadows>1</cast_shadows>
      </visual>
      <visual name='base_fixed_joint_lump__supports_mid_visual_22'>
	<geometry>
	  <mesh>
	    <scale>1 1 1</scale>
	    <uri>model://lander/meshes/supports_mid.stl</uri>
	  </mesh>
	</geometry>
	<pose frame=''>0 0 -0.0575 0 -0 0</pose>
	<material>
	  <shader type='pixel'>
	    <normal_map>__default__</normal_map>
	  </shader>
	  <script>
	    <name>ModelPreview_4::base::base_fixed_joint_lump__supports_mid_visual_22_MATERIAL_</name>
	    <uri>__default__</uri>
	  </script>
	</material>
	<transparency>0</transparency>
	<cast_shadows>1</cast_shadows>
      </visual>
      <visual name='base_fixed_joint_lump__thruster_mount_1_visual_34'>
	<geometry>
	  <mesh>
	    <scale>1 1 1</scale>
	    <uri>model://lander/meshes/thruster_mount_1.stl</uri>
	  </mesh>
	</geometry>
	<pose frame=''>-0.3 0 -0.065 0 -0 0</pose>
	<material>
	  <shader type='pixel'>
	    <normal_map>__default__</normal_map>
	  </shader>
	  <script>
	    <name>ModelPreview_4::base::base_fixed_joint_lump__thruster_mount_1_visual_34_MATERIAL_</name>
	    <uri>__default__</uri>
	  </script>
	</material>
	<transparency>0</transparency>
	<cast_shadows>1</cast_shadows>
      </visual>
      <visual name='base_fixed_joint_lump__thruster_mount_3_visual_40'>
	<geometry>
	  <mesh>
	    <scale>1 1 1</scale>
	    <uri>model://lander/meshes/thruster_mount_3.stl</uri>
	  </mesh>
	</geometry>
	<pose frame=''>0.3 0 -0.065 0 -0 0</pose>
	<material>
	  <shader type='pixel'>
	    <normal_map>__default__</normal_map>
	  </shader>
	  <script>
	    <name>ModelPreview_4::base::base_fixed_joint_lump__thruster_mount_3_visual_40_MATERIAL_</name>
	    <uri>__default__</uri>
	  </script>
	</material>
	<transparency>0</transparency>
	<cast_shadows>1</cast_shadows>
      </visual>
      <visual name='base_fixed_joint_lump__thruster_4_visual_44'>
	<geometry>
	  <mesh>
	    <scale>1 1 1</scale>
	    <uri>model://lander/meshes/thruster_4.stl</uri>
	  </mesh>
	</geometry>
	<pose frame=''>0 0.385 -0.068 0 -0 0</pose>
	<material>
	  <shader type='pixel'>
	    <normal_map>__default__</normal_map>
	  </shader>
	  <script>
	    <name>ModelPreview_4::base::base_fixed_joint_lump__thruster_4_visual_44_MATERIAL_</name>
	    <uri>__default__</uri>
	  </script>
	</material>
	<transparency>0</transparency>
	<cast_shadows>1</cast_shadows>
      </visual>
      <visual name='base_fixed_joint_lump__leg_hinge_3_visual_8'>
	<geometry>
	  <mesh>
	    <scale>1 1 1</scale>
	    <uri>model://lander/meshes/leg_hinge_3.stl</uri>
	  </mesh>
	</geometry>
	<pose frame=''>0.3125 -0.3125 0.015 0 -0 0.7854</pose>
	<material>
	  <shader type='pixel'>
	    <normal_map>__default__</normal_map>
	  </shader>
	  <script>
	    <name>ModelPreview_4::base::base_fixed_joint_lump__leg_hinge_3_visual_8_MATERIAL_</name>
	    <uri>__default__</uri>
	  </script>
	</material>
	<transparency>0</transparency>
	<cast_shadows>1</cast_shadows>
      </visual>
      <visual name='base_fixed_joint_lump__thruster_3_visual_41'>
	<geometry>
	  <mesh>
	    <scale>1 1 1</scale>
	    <uri>model://lander/meshes/thruster_3.stl</uri>
	  </mesh>
	</geometry>
	<pose frame=''>0.385 0 -0.056 0 -0 0</pose>
	<material>
	  <shader type='pixel'>
	    <normal_map>__default__</normal_map>
	  </shader>
	  <script>
	    <name>ModelPreview_4::base::base_fixed_joint_lump__thruster_3_visual_41_MATERIAL_</name>
	    <uri>__default__</uri>
	  </script>
	</material>
	<transparency>0</transparency>
	<cast_shadows>1</cast_shadows>
      </visual>
      <visual name='base_fixed_joint_lump__thruster_mount_4_visual_43'>
	<geometry>
	  <mesh>
	    <scale>1 1 1</scale>
	    <uri>model://lander/meshes/thruster_mount_4.stl</uri>
	  </mesh>
	</geometry>
	<pose frame=''>0 0.3 -0.065 0 -0 0</pose>
	<material>
	  <shader type='pixel'>
	    <normal_map>__default__</normal_map>
	  </shader>
	  <script>
	    <name>ModelPreview_4::base::base_fixed_joint_lump__thruster_mount_4_visual_43_MATERIAL_</name>
	    <uri>__default__</uri>
	  </script>
	</material>
	<transparency>0</transparency>
	<cast_shadows>1</cast_shadows>
      </visual>
      <visual name='base_visual'>
	<geometry>
	  <mesh>
	    <scale>1 1 1</scale>
	    <uri>model://lander/meshes/gas_tank.stl</uri>
	  </mesh>
	</geometry>
	<pose frame=''>0 0 0.09 0 -0 0</pose>
	<material>
	  <shader type='pixel'>
	    <normal_map>__default__</normal_map>
	  </shader>
	  <script>
	    <name>ModelPreview_4::base::base_visual_MATERIAL_</name>
	    <uri>__default__</uri>
	  </script>
	</material>
	<transparency>0</transparency>
	<cast_shadows>1</cast_shadows>
      </visual>
      <visual name='base_fixed_joint_lump__thruster_mount_2_visual_37'>
	<geometry>
	  <mesh>
	    <scale>1 1 1</scale>
	    <uri>model://lander/meshes/thruster_mount_2.stl</uri>
	  </mesh>
	</geometry>
	<pose frame=''>0 -0.3 -0.065 0 -0 0</pose>
	<material>
	  <shader type='pixel'>
	    <normal_map>__default__</normal_map>
	  </shader>
	  <script>
	    <name>ModelPreview_4::base::base_fixed_joint_lump__thruster_mount_2_visual_37_MATERIAL_</name>
	    <uri>__default__</uri>
	  </script>
	</material>
	<transparency>0</transparency>
	<cast_shadows>1</cast_shadows>
      </visual>
      <visual name='base_fixed_joint_lump__platform_top_visual_1'>
	<geometry>
	  <mesh>
	    <scale>1 1 1</scale>
	    <uri>model://lander/meshes/platform_top.stl</uri>
	  </mesh>
	</geometry>
	<pose frame=''>0 0 0.034 0 -0 0</pose>
	<material>
	  <shader type='pixel'>
	    <normal_map>__default__</normal_map>
	  </shader>
	  <script>
	    <name>ModelPreview_4::base::base_fixed_joint_lump__platform_top_visual_1_MATERIAL_</name>
	    <uri>__default__</uri>
	  </script>
	</material>
	<transparency>0</transparency>
	<cast_shadows>1</cast_shadows>
      </visual>
      <visual name='base_fixed_joint_lump__leg_hinge_2_visual_6'>
	<geometry>
	  <mesh>
	    <scale>1 1 1</scale>
	    <uri>model://lander/meshes/leg_hinge_2.stl</uri>
	  </mesh>
	</geometry>
	<pose frame=''>0.3125 0.3125 0.015 0 0 -0.7854</pose>
	<material>
	  <shader type='pixel'>
	    <normal_map>__default__</normal_map>
	  </shader>
	  <script>
	    <name>ModelPreview_4::base::base_fixed_joint_lump__leg_hinge_2_visual_6_MATERIAL_</name>
	    <uri>__default__</uri>
	  </script>
	</material>
	<transparency>0</transparency>
	<cast_shadows>1</cast_shadows>
      </visual>
      <visual name='base_fixed_joint_lump__supports_bottom_visual_23'>
	<geometry>
	  <mesh>
	    <scale>1 1 1</scale>
	    <uri>model://lander/meshes/supports_bottom.stl</uri>
	  </mesh>
	</geometry>
	<pose frame=''>0 0 -0.1325 -9.3e-05 9.3e-05 -1.57089</pose>
	<material>
	  <shader type='pixel'>
	    <normal_map>__default__</normal_map>
	  </shader>
	  <script>
	    <name>ModelPreview_4::base::base_fixed_joint_lump__supports_bottom_visual_23_MATERIAL_</name>
	    <uri>__default__</uri>
	  </script>
	</material>
	<transparency>0</transparency>
	<cast_shadows>1</cast_shadows>
      </visual>
      <visual name='base_fixed_joint_lump__platform_bottom_visual_24'>
	<geometry>
	  <mesh>
	    <scale>1 1 1</scale>
	    <uri>model://lander/meshes/platform_bottom.stl</uri>
	  </mesh>
	</geometry>
	<pose frame=''>0 0 -0.145 0 -0 0</pose>
	<material>
	  <shader type='pixel'>
	    <normal_map>__default__</normal_map>
	  </shader>
	  <script>
	    <name>ModelPreview_4::base::base_fixed_joint_lump__platform_bottom_visual_24_MATERIAL_</name>
	    <uri>__default__</uri>
	  </script>
	</material>
	<transparency>0</transparency>
	<cast_shadows>1</cast_shadows>
      </visual>
      <visual name='base_fixed_joint_lump__thruster_2_visual_38'>
	<geometry>
	  <mesh>
	    <scale>1 1 1</scale>
	    <uri>model://lander/meshes/thruster_2.stl</uri>
	  </mesh>
	</geometry>
	<pose frame=''>0 -0.385 -0.07 0 -0 0</pose>
	<material>
	  <shader type='pixel'>
	    <normal_map>__default__</normal_map>
	  </shader>
	  <script>
	    <name>ModelPreview_4::base::base_fixed_joint_lump__thruster_2_visual_38_MATERIAL_</name>
	    <uri>__default__</uri>
	  </script>
	</material>
	<transparency>0</transparency>
	<cast_shadows>1</cast_shadows>
      </visual>
    </link>
    <link name='actuator_1_inner'>
      <self_collide>0</self_collide>
      <inertial>
	<inertia>
	  <ixx>1</ixx>
	  <ixy>0</ixy>
	  <ixz>0</ixz>
	  <iyy>1</iyy>
	  <iyz>0</iyz>
	  <izz>1</izz>
	</inertia>
	<mass>0.45</mass>
	<pose frame=''>0 0 0 0 -0 0</pose>
      </inertial>
      <enable_wind>0</enable_wind>
      <kinematic>0</kinematic>
      <gravity>1</gravity>
      <pose frame=''>0.133874 -0.133918 0.119689 0 0 -0.7854</pose>
      <visual name='base_fixed_joint_lump__actuator_1_inner_visual_27'>
	<geometry>
	  <mesh>
	    <scale>1 1 1</scale>
	    <uri>model://lander/meshes/actuator_1_inner.stl</uri>
	  </mesh>
	</geometry>
	<pose frame=''>0 0 0 0 -0 0</pose>
	<material>
	  <shader type='pixel'/>
	</material>
	<transparency>0</transparency>
	<cast_shadows>1</cast_shadows>
      </visual>
    </link>
    <link name='actuator_1_mount_back'>
      <self_collide>0</self_collide>
      <inertial>
	<inertia>
	  <ixx>1</ixx>
	  <ixy>0</ixy>
	  <ixz>0</ixz>
	  <iyy>1</iyy>
	  <iyz>0</iyz>
	  <izz>1</izz>
	</inertia>
	<mass>.1</mass>
	<pose frame=''>0 0 0 0 -0 0</pose>
      </inertial>
      <enable_wind>0</enable_wind>
      <kinematic>0</kinematic>
      <gravity>1</gravity>
      <pose frame=''>0.265 -0.265 0.146205 0 -0 0</pose>
      <visual name='base_fixed_joint_lump__actuator_1_back_mount_visual_25'>
	<geometry>
	  <mesh>
	    <scale>1 1 1</scale>
	    <uri>model://lander/meshes/actuator_1_mount_back.stl</uri>
	  </mesh>
	</geometry>
	<pose frame=''>0 0 0 0 -0 0</pose>
	<material>
	  <shader type='pixel'>
	    <normal_map>__default__</normal_map>
	  </shader>
	  <emissive>0 0 0 1</emissive>
	  <script>
	    <name>ModelPreview_10::actuator_1_mount_back::base_fixed_joint_lump__actuator_1_back_mount_visual_25_MATERIAL_</name>
	    <uri>__default__</uri>
	  </script>
	</material>
	<transparency>0</transparency>
	<cast_shadows>1</cast_shadows>
      </visual>
      <collision name='collision_1'>
	<laser_retro>0</laser_retro>
	<max_contacts>10</max_contacts>
	<pose frame=''>0 0 0 0 -0 0</pose>
	<geometry>
	  <mesh>
	    <uri>model://lander/meshes/actuator_1_mount_back.stl</uri>
	    <scale>0.022668 0.022668 0.061913</scale>
	  </mesh>
	</geometry>
	<surface>
	  <friction>
	    <ode>
	      <mu>1</mu>
	      <mu2>1</mu2>
	      <fdir1>0 0 0</fdir1>
	      <slip1>0</slip1>
	      <slip2>0</slip2>
	    </ode>
	    <torsional>
	      <coefficient>1</coefficient>
	      <patch_radius>0</patch_radius>
	      <surface_radius>0</surface_radius>
	      <use_patch_radius>1</use_patch_radius>
	      <ode>
		<slip>0</slip>
	      </ode>
	    </torsional>
	  </friction>
	  <bounce>
	    <restitution_coefficient>0</restitution_coefficient>
	    <threshold>1e+06</threshold>
	  </bounce>
	  <contact>
	    <collide_without_contact>0</collide_without_contact>
	    <collide_without_contact_bitmask>1</collide_without_contact_bitmask>
	    <collide_bitmask>1</collide_bitmask>
	    <ode>
	      <soft_cfm>0</soft_cfm>
	      <soft_erp>0.2</soft_erp>
	      <kp>1e+13</kp>
	      <kd>1</kd>
	      <max_vel>0.01</max_vel>
	      <min_depth>0</min_depth>
	    </ode>
	    <bullet>
	      <split_impulse>1</split_impulse>
	      <split_impulse_penetration_threshold>-0.01</split_impulse_penetration_threshold>
	      <soft_cfm>0</soft_cfm>
	      <soft_erp>0.2</soft_erp>
	      <kp>1e+13</kp>
	      <kd>1</kd>
	    </bullet>
	  </contact>
	</surface>
      </collision>
    </link>
    <link name='actuator_1_mount_front'>
      <self_collide>0</self_collide>
      <inertial>
	<inertia>
	  <ixx>1</ixx>
	  <ixy>0</ixy>
	  <ixz>0</ixz>
	  <iyy>1</iyy>
	  <iyz>0</iyz>
	  <izz>1</izz>
	</inertia>
	<mass>.1</mass>
	<pose frame=''>0 0 0 0 -0 0</pose>
      </inertial>
      <enable_wind>0</enable_wind>
      <kinematic>0</kinematic>
      <gravity>1</gravity>
      <pose frame=''>0.074 -0.074326 0.119514 0 -0 2.354</pose>
      <visual name='base_fixed_joint_lump__actuator_1_mount_front_visual_28'>
	<geometry>
	  <mesh>
	    <scale>1 1 1</scale>
	    <uri>model://lander/meshes/actuator_1_mount_front.stl</uri>
	  </mesh>
	</geometry>
	<pose frame=''>0 0 0 0 -0 0</pose>
	<material>
	  <shader type='pixel'/>
	</material>
	<transparency>0</transparency>
	<cast_shadows>1</cast_shadows>
      </visual>
    </link>
    <link name='actuator_1_outer'>
      <self_collide>1</self_collide>
      <inertial>
	<inertia>
	  <ixx>0</ixx>
	  <ixy>0</ixy>
	  <ixz>0</ixz>
	  <iyy>0</iyy>
	  <iyz>0</iyz>
	  <izz>0</izz>
	</inertia>
	<mass>.5835</mass>
	<pose frame=''>0 0 0 0 -0 0</pose>
      </inertial>
      <enable_wind>0</enable_wind>
      <kinematic>0</kinematic>
      <gravity>1</gravity>
      <pose frame=''>0.200848 -0.200848 0.10934 0 0 -0.7854</pose>
      <visual name='base_fixed_joint_lump__actuator_1_outer_visual_26'>
	<geometry>
	  <mesh>
	    <scale>1 1 1</scale>
	    <uri>model://lander/meshes/actuator_1_outer.stl</uri>
	  </mesh>
	</geometry>
	<pose frame=''>0 0 0 0 -0 0</pose>
	<material>
	  <shader type='pixel'>
	    <normal_map>__default__</normal_map>
	  </shader>
	  <emissive>0 0 0 1</emissive>
	  <script>
	    <name>ModelPreview_10::actuator_1_outer::base_fixed_joint_lump__actuator_1_outer_visual_26_MATERIAL_</name>
	    <uri>__default__</uri>
	  </script>
	</material>
	<transparency>0</transparency>
	<cast_shadows>1</cast_shadows>
      </visual>
      <collision name='collision_0'>
	<laser_retro>0</laser_retro>
	<max_contacts>10</max_contacts>
	<pose frame=''>0 0 0 0 -0 0</pose>
	<geometry>
	  <mesh>
	    <uri>model://lander/meshes/actuator_1_outer.stl</uri>
	    <scale>0.213909 0.04 0.078104</scale>
	  </mesh>
	</geometry>
	<surface>
	  <friction>
	    <ode>
	      <mu>1</mu>
	      <mu2>1</mu2>
	      <fdir1>0 0 0</fdir1>
	      <slip1>0</slip1>
	      <slip2>0</slip2>
	    </ode>
	    <torsional>
	      <coefficient>1</coefficient>
	      <patch_radius>0</patch_radius>
	      <surface_radius>0</surface_radius>
	      <use_patch_radius>1</use_patch_radius>
	      <ode>
		<slip>0</slip>
	      </ode>
	    </torsional>
	  </friction>
	  <bounce>
	    <restitution_coefficient>0</restitution_coefficient>
	    <threshold>1e+06</threshold>
	  </bounce>
	  <contact>
	    <collide_without_contact>0</collide_without_contact>
	    <collide_without_contact_bitmask>1</collide_without_contact_bitmask>
	    <collide_bitmask>1</collide_bitmask>
	    <ode>
	      <soft_cfm>0</soft_cfm>
	      <soft_erp>0.2</soft_erp>
	      <kp>1e+13</kp>
	      <kd>1</kd>
	      <max_vel>0.01</max_vel>
	      <min_depth>0</min_depth>
	    </ode>
	    <bullet>
	      <split_impulse>1</split_impulse>
	      <split_impulse_penetration_threshold>-0.01</split_impulse_penetration_threshold>
	      <soft_cfm>0</soft_cfm>
	      <soft_erp>0.2</soft_erp>
	      <kp>1e+13</kp>
	      <kd>1</kd>
	    </bullet>
	  </contact>
	</surface>
      </collision>
    </link>
    <link name='actuator_2_inner'>
      <self_collide>0</self_collide>
      <inertial>
	<inertia>
	  <ixx>1</ixx>
	  <ixy>0</ixy>
	  <ixz>0</ixz>
	  <iyy>1</iyy>
	  <iyz>0</iyz>
	  <izz>1</izz>
	</inertia>
	<mass>.45</mass>
	<pose frame=''>0 0 0 0 -0 0</pose>
      </inertial>
      <enable_wind>0</enable_wind>
      <kinematic>0</kinematic>
      <gravity>1</gravity>
      <pose frame=''>0.120745 0.120746 0.117493 0 -0 0.7854</pose>
      <visual name='base_fixed_joint_lump__actuator_2_inner_visual_31'>
	<geometry>
	  <mesh>
	    <scale>1 1 1</scale>
	    <uri>model://lander/meshes/actuator_2_inner.stl</uri>
	  </mesh>
	</geometry>
	<cast_shadows>1</cast_shadows>
	<pose frame=''>0 0 0 0 -0 0</pose>
	<material>
	  <shader type='pixel'/>
	</material>
	<transparency>0</transparency>
      </visual>
    </link>
    <link name='actuator_2_mount_back'>
      <self_collide>0</self_collide>
      <inertial>
	<inertia>
	  <ixx>1</ixx>
	  <ixy>0</ixy>
	  <ixz>0</ixz>
	  <iyy>1</iyy>
	  <iyz>0</iyz>
	  <izz>1</izz>
	</inertia>
	<mass>.1</mass>
	<pose frame=''>0 0 0 0 -0 0</pose>
      </inertial>
      <enable_wind>0</enable_wind>
      <kinematic>0</kinematic>
      <gravity>1</gravity>
      <pose frame=''>0.265 0.265 0.146522 0 -0 0</pose>
      <visual name='base_fixed_joint_lump__actuator_2_mount_back_visual_29'>
	<geometry>
	  <mesh>
	    <scale>1 1 1</scale>
	    <uri>model://lander/meshes/actuator_2_mount_back.stl</uri>
	  </mesh>
	</geometry>
	<cast_shadows>1</cast_shadows>
	<pose frame=''>0 0 0 0 -0 0</pose>
	<material>
	  <shader type='pixel'/>
	  <emissive>0 0 0 1</emissive>
	</material>
	<transparency>0</transparency>
      </visual>
    </link>
    <link name='actuator_2_mount_front'>
      <self_collide>0</self_collide>
      <inertial>
	<inertia>
	  <ixx>1</ixx>
	  <ixy>0</ixy>
	  <ixz>0</ixz>
	  <iyy>1</iyy>
	  <iyz>0</iyz>
	  <izz>1</izz>
	</inertia>
	<mass>.1</mass>
	<pose frame=''>0 0 0 0 -0 0</pose>
      </inertial>
      <enable_wind>0</enable_wind>
      <kinematic>0</kinematic>
      <gravity>1</gravity>
      <pose frame=''>0.060611 0.060611 0.117573 0 -0 0.7854</pose>
      <visual name='base_fixed_joint_lump__actuator_2_mount_front_visual_32'>
	<geometry>
	  <mesh>
	    <scale>1 1 1</scale>
	    <uri>model://lander/meshes/actuator_2_mount_front.stl</uri>
	  </mesh>
	</geometry>
	<pose frame=''>0 0 0 0 -0 0</pose>
	<material>
	  <shader type='pixel'/>
	</material>
	<transparency>0</transparency>
	<cast_shadows>1</cast_shadows>
      </visual>
    </link>
    <link name='actuator_2_outer'>
      <self_collide>0</self_collide>
      <inertial>
	<inertia>
	  <ixx>1</ixx>
	  <ixy>0</ixy>
	  <ixz>0</ixz>
	  <iyy>1</iyy>
	  <iyz>0</iyz>
	  <izz>1</izz>
	</inertia>
	<mass>.5835</mass>
	<pose frame=''>0 0 0 0 -0 0</pose>
      </inertial>
      <enable_wind>0</enable_wind>
      <kinematic>0</kinematic>
      <gravity>1</gravity>
      <pose frame=''>0.200785 0.200785 0.110529 0 -0 0.7854</pose>
      <visual name='base_fixed_joint_lump__actuator_2_outer_visual_30'>
	<geometry>
	  <mesh>
	    <scale>1 1 1</scale>
	    <uri>model://lander/meshes/actuator_2_outer.stl</uri>
	  </mesh>
	</geometry>
	<pose frame=''>0 0 0 0 -0 0</pose>
	<material>
	  <shader type='pixel'/>
	  <emissive>0 0 0 1</emissive>
	</material>
	<transparency>0</transparency>
	<cast_shadows>1</cast_shadows>
      </visual>
    </link>
    <link name='gimbal_actuator_mount_1'>
      <self_collide>0</self_collide>
      <inertial>
	<inertia>
	  <ixx>1</ixx>
	  <ixy>0</ixy>
	  <ixz>0</ixz>
	  <iyy>1</iyy>
	  <iyz>0</iyz>
	  <izz>1</izz>
	</inertia>
	<mass>.1</mass>
	<pose frame=''>0 0 0 0 -0 0</pose>
      </inertial>
      <enable_wind>0</enable_wind>
      <kinematic>0</kinematic>
      <gravity>1</gravity>
      <pose frame=''>0.056078 0.056079 0.182666 0 -0 0.7854</pose>
      <visual name='base_fixed_joint_lump__gimbal_actuator_mount_1_visual_17'>
	<geometry>
	  <mesh>
	    <scale>1 1 1</scale>
	    <uri>model://lander/meshes/gimbal_actuator_mount_1.stl</uri>
	  </mesh>
	</geometry>
	<pose frame=''>0 0 0 0 -0 0</pose>
	<material>
	  <shader type='pixel'/>
	</material>
	<transparency>0</transparency>
	<cast_shadows>1</cast_shadows>
      </visual>
    </link>
    <link name='gimbal_actuator_mount_2'>
      <self_collide>0</self_collide>
      <inertial>
	<inertia>
	  <ixx>1</ixx>
	  <ixy>0</ixy>
	  <ixz>0</ixz>
	  <iyy>1</iyy>
	  <iyz>0</iyz>
	  <izz>1</izz>
	</inertia>
	<mass>.1</mass>
	<pose frame=''>0 0 0 0 -0 0</pose>
      </inertial>
      <enable_wind>0</enable_wind>
      <kinematic>0</kinematic>
      <gravity>1</gravity>
      <pose frame=''>0.065933 -0.061161 0.173778 0 0 -0.7854</pose>
      <visual name='base_fixed_joint_lump__gimbal_actuator_mount_2_visual_16'>
	<geometry>
	  <mesh>
	    <scale>1 1 1</scale>
	    <uri>model://lander/meshes/gimbal_actuator_mount_2.stl</uri>
	  </mesh>
	</geometry>
	<pose frame=''>0 0 0 0 -0 0</pose>
	<material>
	  <shader type='pixel'/>
	</material>
	<transparency>0</transparency>
	<cast_shadows>1</cast_shadows>
      </visual>
    </link>
    <link name='gimbal_mid_rotate_1'>
      <self_collide>0</self_collide>
      <inertial>
	<inertia>
	  <ixx>1</ixx>
	  <ixy>0</ixy>
	  <ixz>0</ixz>
	  <iyy>1</iyy>
	  <iyz>0</iyz>
	  <izz>1</izz>
	</inertia>
	<mass>.1</mass>
	<pose frame=''>0 0 0 0 -0 0</pose>
      </inertial>
      <enable_wind>0</enable_wind>
      <kinematic>0</kinematic>
      <gravity>1</gravity>
      <pose frame=''>0.067948 0.067947 0.224251 0 0 -0.7854</pose>
      <visual name='base_fixed_joint_lump__gimbal_mid_rotate_1_visual_18'>
	<geometry>
	  <mesh>
	    <scale>1 1 1</scale>
	    <uri>model://lander/meshes/gimbal_mid_rotate_1.stl</uri>
	  </mesh>
	</geometry>
	<pose frame=''>0 0 0 0 -0 0</pose>
	<material>
	  <shader type='pixel'/>
	</material>
	<transparency>0</transparency>
	<cast_shadows>1</cast_shadows>
      </visual>
    </link>
    <link name='gimbal_mid_rotate_2'>
      <self_collide>0</self_collide>
      <inertial>
	<inertia>
	  <ixx>1</ixx>
	  <ixy>0</ixy>
	  <ixz>0</ixz>
	  <iyy>1</iyy>
	  <iyz>0</iyz>
	  <izz>1</izz>
	</inertia>
	<mass>.1</mass>
	<pose frame=''>0 0 0 0 -0 0</pose>
      </inertial>
      <enable_wind>0</enable_wind>
      <kinematic>0</kinematic>
      <gravity>1</gravity>
      <pose frame=''>-0.067201 -0.067201 0.221949 0 0 -0.7854</pose>
      <visual name='base_fixed_joint_lump__gimbal_mid_rotate_2_visual_19'>
	<geometry>
	  <mesh>
	    <scale>1 1 1</scale>
	    <uri>model://lander/meshes/gimbal_mid_rotate_2.stl</uri>
	  </mesh>
	</geometry>
	<pose frame=''>0 0 0 0 -0 0</pose>
	<material>
	  <shader type='pixel'/>
	</material>
	<transparency>0</transparency>
	<cast_shadows>1</cast_shadows>
      </visual>
    </link>
    <link name='gimbal_outer_rotate_1'>
      <self_collide>0</self_collide>
      <inertial>
	<inertia>
	  <ixx>1</ixx>
	  <ixy>0</ixy>
	  <ixz>0</ixz>
	  <iyy>1</iyy>
	  <iyz>0</iyz>
	  <izz>1</izz>
	</inertia>
	<mass>.1</mass>
	<pose frame=''>0 0 0 0 -0 0</pose>
      </inertial>
      <enable_wind>0</enable_wind>
      <kinematic>0</kinematic>
      <gravity>1</gravity>
      <pose frame=''>0.101728 -0.101728 0.22545 0 0 -0.7854</pose>
      <visual name='base_fixed_joint_lump__gimbal_outer_rotate_1_visual_20'>
	<geometry>
	  <mesh>
	    <scale>1 1 1</scale>
	    <uri>model://lander/meshes/gimbal_outer_rotate_1.stl</uri>
	  </mesh>
	</geometry>
	<cast_shadows>1</cast_shadows>
	<pose frame=''>0 0 0 0 -0 0</pose>
	<material>
	  <shader type='pixel'/>
	</material>
	<transparency>0</transparency>
      </visual>
    </link>
    <link name='gimbal_outer_rotate_2'>
      <self_collide>0</self_collide>
      <inertial>
	<inertia>
	  <ixx>1</ixx>
	  <ixy>0</ixy>
	  <ixz>0</ixz>
	  <iyy>1</iyy>
	  <iyz>0</iyz>
	  <izz>1</izz>
	</inertia>
	<mass>.1</mass>
	<pose frame=''>0 0 0 0 -0 0</pose>
      </inertial>
      <enable_wind>0</enable_wind>
      <kinematic>0</kinematic>
      <gravity>1</gravity>
      <pose frame=''>-0.100497 0.100498 0.224114 0 0 -0.7854</pose>
      <visual name='base_fixed_joint_lump__gimbal_outer_rotate_2_visual_21'>
	<geometry>
	  <mesh>
	    <scale>1 1 1</scale>
	    <uri>model://lander/meshes/gimbal_outer_rotate_2.stl</uri>
	  </mesh>
	</geometry>
	<pose frame=''>0 0 0 0 -0 0</pose>
	<material>
	  <shader type='pixel'/>
	</material>
	<transparency>0</transparency>
	<cast_shadows>1</cast_shadows>
      </visual>
    </link>
    <link name='gimbal_ring_inner'>
      <self_collide>0</self_collide>
      <inertial>
	<inertia>
	  <ixx>1</ixx>
	  <ixy>0</ixy>
	  <ixz>0</ixz>
	  <iyy>1</iyy>
	  <iyz>0</iyz>
	  <izz>1</izz>
	</inertia>
	<mass>.400528</mass>
	<pose frame=''>0 0 0 0 -0 0</pose>
      </inertial>
      <enable_wind>0</enable_wind>
      <kinematic>0</kinematic>
      <gravity>1</gravity>
      <pose frame=''>-0 0 0.22074 0 -0 0</pose>
      <visual name='base_fixed_joint_lump__gimbal_inner_visual_15'>
	<geometry>
	  <mesh>
	    <scale>1 1 1</scale>
	    <uri>model://lander/meshes/gimbal_inner.stl</uri>
	  </mesh>
	</geometry>
	<pose frame=''>0 0 0 0 -0 0</pose>
	<material>
	  <shader type='pixel'/>
	</material>
	<transparency>0</transparency>
	<cast_shadows>1</cast_shadows>
      </visual>
    </link>
    <link name='gimbal_ring_mid'>
      <self_collide>0</self_collide>
      <inertial>
	<inertia>
	  <ixx>1</ixx>
	  <ixy>0</ixy>
	  <ixz>0</ixz>
	  <iyy>1</iyy>
	  <iyz>0</iyz>
	  <izz>1</izz>
	</inertia>
	<mass>.548487</mass>
	<pose frame=''>0 0 0 0 -0 0</pose>
      </inertial>
      <enable_wind>0</enable_wind>
      <kinematic>0</kinematic>
      <gravity>1</gravity>
      <pose frame=''>0 -0 0.223638 0 -0 0</pose>
      <visual name='base_fixed_joint_lump__gimbal_mid_visual_14'>
	<geometry>
	  <mesh>
	    <scale>1 1 1</scale>
	    <uri>model://lander/meshes/gimbal_mid.stl</uri>
	  </mesh>
	</geometry>
	<pose frame=''>0 0 0 0 -0 0</pose>
	<material>
	  <shader type='pixel'/>
	</material>
	<transparency>0</transparency>
	<cast_shadows>1</cast_shadows>
      </visual>
    </link>
    <link name='gimbal_ring_outer'>
      <self_collide>0</self_collide>
      <inertial>
	<inertia>
	  <ixx>1</ixx>
	  <ixy>0</ixy>
	  <ixz>0</ixz>
	  <iyy>1</iyy>
	  <iyz>0</iyz>
	  <izz>1</izz>
	</inertia>
	<mass>.850983</mass>
	<pose frame=''>0 0 0 0 -0 0</pose>
      </inertial>
      <enable_wind>0</enable_wind>
      <kinematic>0</kinematic>
      <gravity>1</gravity>
      <pose frame=''>-0 -0 0.217348 0 -0 0</pose>
      <visual name='base_fixed_joint_lump__gimbal_outer_visual_13'>
	<geometry>
	  <mesh>
	    <scale>1 1 1</scale>
	    <uri>model://lander/meshes/gimbal_outer.stl</uri>
	  </mesh>
	</geometry>
	<pose frame=''>0 0 0 0 -0 0</pose>
	<material>
	  <shader type='pixel'/>
	</material>
	<transparency>0</transparency>
	<cast_shadows>1</cast_shadows>
      </visual>
    </link>
    <link name='leg_1'>
      <self_collide>0</self_collide>
      <inertial>
	<pose frame=''>0 0 0 0 -0 0</pose>
	<inertia>
	  <ixx>1</ixx>
	  <ixy>0</ixy>
	  <ixz>0</ixz>
	  <iyy>1</iyy>
	  <iyz>0</iyz>
	  <izz>1</izz>
	</inertia>
	<mass>.047972</mass>
      </inertial>
      <enable_wind>0</enable_wind>
      <kinematic>0</kinematic>
      <pose frame=''>-0.463 0.463 0.0015 0.5236 -0 0.7854</pose>
      <gravity>1</gravity>
      <visual name='base_fixed_joint_lump__leg_1_visual_5'>
	<geometry>
	  <mesh>
	    <scale>1 1 1</scale>
	    <uri>model://lander/meshes/leg_1.stl</uri>
	  </mesh>
	</geometry>
	<pose frame=''>0 0 0 0 -0 0</pose>
	<material>
	  <shader type='pixel'>
	    <normal_map>__default__</normal_map>
	  </shader>
	  <emissive>0 0 0 1</emissive>
	  <script>
	    <name>ModelPreview_14::leg_1::base_fixed_joint_lump__leg_1_visual_5_MATERIAL_</name>
	    <uri>__default__</uri>
	  </script>
	</material>
	<transparency>0</transparency>
	<cast_shadows>1</cast_shadows>
      </visual>
      <collision name='collision_1'>
	<laser_retro>0</laser_retro>
	<max_contacts>10</max_contacts>
	<pose frame=''>0 0 -0.08 0 -0 0</pose>
	<geometry>
	  <box>
	    <size>0.0889 0.074097 0.960288</size>
	  </box>
	</geometry>
	<surface>
	  <friction>
	    <ode>
	      <mu>1</mu>
	      <mu2>1</mu2>
	      <fdir1>0 0 0</fdir1>
	      <slip1>0</slip1>
	      <slip2>0</slip2>
	    </ode>
	    <torsional>
	      <coefficient>1</coefficient>
	      <patch_radius>0</patch_radius>
	      <surface_radius>0</surface_radius>
	      <use_patch_radius>1</use_patch_radius>
	      <ode>
		<slip>0</slip>
	      </ode>
	    </torsional>
	  </friction>
	  <bounce>
	    <restitution_coefficient>0</restitution_coefficient>
	    <threshold>1e+06</threshold>
	  </bounce>
	  <contact>
	    <collide_without_contact>0</collide_without_contact>
	    <collide_without_contact_bitmask>1</collide_without_contact_bitmask>
	    <collide_bitmask>1</collide_bitmask>
	    <ode>
	      <soft_cfm>0</soft_cfm>
	      <soft_erp>0.2</soft_erp>
	      <kp>1e+13</kp>
	      <kd>1</kd>
	      <max_vel>0.01</max_vel>
	      <min_depth>0</min_depth>
	    </ode>
	    <bullet>
	      <split_impulse>1</split_impulse>
	      <split_impulse_penetration_threshold>-0.01</split_impulse_penetration_threshold>
	      <soft_cfm>0</soft_cfm>
	      <soft_erp>0.2</soft_erp>
	      <kp>1e+13</kp>
	      <kd>1</kd>
	    </bullet>
	  </contact>
	</surface>
      </collision>
    </link>
    <link name='leg_2'>
      <self_collide>0</self_collide>
      <inertial>
	<pose frame=''>0 0 0 0 -0 0</pose>
	<inertia>
	  <ixx>1</ixx>
	  <ixy>0</ixy>
	  <ixz>0</ixz>
	  <iyy>1</iyy>
	  <iyz>0</iyz>
	  <izz>1</izz>
	</inertia>
	<mass>.047972</mass>
      </inertial>
      <enable_wind>0</enable_wind>
      <kinematic>0</kinematic>
      <pose frame=''>0.463 0.463 0.0015 0.5236 -0 -0.7854</pose>
      <gravity>1</gravity>
      <visual name='base_fixed_joint_lump__leg_2_visual_7'>
	<geometry>
	  <mesh>
	    <scale>1 1 1</scale>
	    <uri>model://lander/meshes/leg_2.stl</uri>
	  </mesh>
	</geometry>
	<pose frame=''>0 0 0 0 -0 0</pose>
	<material>
	  <shader type='pixel'>
	    <normal_map>__default__</normal_map>
	  </shader>
	  <emissive>0 0 0 1</emissive>
	  <script>
	    <name>ModelPreview_20::leg_2::base_fixed_joint_lump__leg_2_visual_7_MATERIAL_</name>
	    <uri>__default__</uri>
	  </script>
	</material>
	<transparency>0</transparency>
	<cast_shadows>1</cast_shadows>
      </visual>
      <collision name='collision_0'>
	<laser_retro>0</laser_retro>
	<max_contacts>10</max_contacts>
	<pose frame=''>0 0 -0.08 0 -0 0</pose>
	<geometry>
	  <box>
	    <size>0.0889 0.074097 0.960288</size>
	  </box>
	</geometry>
	<surface>
	  <friction>
	    <ode>
	      <mu>1</mu>
	      <mu2>1</mu2>
	      <fdir1>0 0 0</fdir1>
	      <slip1>0</slip1>
	      <slip2>0</slip2>
	    </ode>
	    <torsional>
	      <coefficient>1</coefficient>
	      <patch_radius>0</patch_radius>
	      <surface_radius>0</surface_radius>
	      <use_patch_radius>1</use_patch_radius>
	      <ode>
		<slip>0</slip>
	      </ode>
	    </torsional>
	  </friction>
	  <bounce>
	    <restitution_coefficient>0</restitution_coefficient>
	    <threshold>1e+06</threshold>
	  </bounce>
	  <contact>
	    <collide_without_contact>0</collide_without_contact>
	    <collide_without_contact_bitmask>1</collide_without_contact_bitmask>
	    <collide_bitmask>1</collide_bitmask>
	    <ode>
	      <soft_cfm>0</soft_cfm>
	      <soft_erp>0.2</soft_erp>
	      <kp>1e+13</kp>
	      <kd>1</kd>
	      <max_vel>0.01</max_vel>
	      <min_depth>0</min_depth>
	    </ode>
	    <bullet>
	      <split_impulse>1</split_impulse>
	      <split_impulse_penetration_threshold>-0.01</split_impulse_penetration_threshold>
	      <soft_cfm>0</soft_cfm>
	      <soft_erp>0.2</soft_erp>
	      <kp>1e+13</kp>
	      <kd>1</kd>
	    </bullet>
	  </contact>
	</surface>
      </collision>
    </link>
    <link name='leg_3'>
      <self_collide>0</self_collide>
      <inertial>
	<pose frame=''>0 0 0 0 -0 0</pose>
	<inertia>
	  <ixx>1</ixx>
	  <ixy>0</ixy>
	  <ixz>0</ixz>
	  <iyy>1</iyy>
	  <iyz>0</iyz>
	  <izz>1</izz>
	</inertia>
	<mass>.047972</mass>
      </inertial>
      <enable_wind>0</enable_wind>
      <kinematic>0</kinematic>
      <pose frame=''>0.463 -0.463 0.0015 -0.5236 -0 0.7854</pose>
      <gravity>1</gravity>
      <visual name='base_fixed_joint_lump__leg_3_visual_9'>
	<geometry>
	  <mesh>
	    <scale>1 1 1</scale>
	    <uri>model://lander/meshes/leg_3.stl</uri>
	  </mesh>
	</geometry>
	<pose frame=''>0 0 0 0 -0 0</pose>
	<material>
	  <shader type='pixel'>
	    <normal_map>__default__</normal_map>
	  </shader>
	  <emissive>0 0 0 1</emissive>
	  <script>
	    <name>ModelPreview_20::leg_3::base_fixed_joint_lump__leg_3_visual_9_MATERIAL_</name>
	    <uri>__default__</uri>
	  </script>
	</material>
	<transparency>0</transparency>
	<cast_shadows>1</cast_shadows>
      </visual>
      <collision name='collision_0'>
	<laser_retro>0</laser_retro>
	<max_contacts>10</max_contacts>
	<pose frame=''>0 0 -0.08 0 -0 0</pose>
	<geometry>
	  <box>
	    <size>0.089004 0.074221 0.960287</size>
	  </box>
	</geometry>
	<surface>
	  <friction>
	    <ode>
	      <mu>1</mu>
	      <mu2>1</mu2>
	      <fdir1>0 0 0</fdir1>
	      <slip1>0</slip1>
	      <slip2>0</slip2>
	    </ode>
	    <torsional>
	      <coefficient>1</coefficient>
	      <patch_radius>0</patch_radius>
	      <surface_radius>0</surface_radius>
	      <use_patch_radius>1</use_patch_radius>
	      <ode>
		<slip>0</slip>
	      </ode>
	    </torsional>
	  </friction>
	  <bounce>
	    <restitution_coefficient>0</restitution_coefficient>
	    <threshold>1e+06</threshold>
	  </bounce>
	  <contact>
	    <collide_without_contact>0</collide_without_contact>
	    <collide_without_contact_bitmask>1</collide_without_contact_bitmask>
	    <collide_bitmask>1</collide_bitmask>
	    <ode>
	      <soft_cfm>0</soft_cfm>
	      <soft_erp>0.2</soft_erp>
	      <kp>1e+13</kp>
	      <kd>1</kd>
	      <max_vel>0.01</max_vel>
	      <min_depth>0</min_depth>
	    </ode>
	    <bullet>
	      <split_impulse>1</split_impulse>
	      <split_impulse_penetration_threshold>-0.01</split_impulse_penetration_threshold>
	      <soft_cfm>0</soft_cfm>
	      <soft_erp>0.2</soft_erp>
	      <kp>1e+13</kp>
	      <kd>1</kd>
	    </bullet>
	  </contact>
	</surface>
      </collision>
    </link>
    <link name='leg_4'>
      <self_collide>0</self_collide>
      <inertial>
	<pose frame=''>0 0 0 0 -0 0</pose>
	<inertia>
	  <ixx>1</ixx>
	  <ixy>0</ixy>
	  <ixz>0</ixz>
	  <iyy>1</iyy>
	  <iyz>0</iyz>
	  <izz>1</izz>
	</inertia>
	<mass>.047972</mass>
      </inertial>
      <enable_wind>0</enable_wind>
      <kinematic>0</kinematic>
      <pose frame=''>-0.463 -0.463 0.0015 -0.5236 -0 -0.7854</pose>
      <gravity>1</gravity>
      <visual name='base_fixed_joint_lump__leg_4_visual_11'>
	<geometry>
	  <mesh>
	    <scale>1 1 1</scale>
	    <uri>model://lander/meshes/leg_4.stl</uri>
	  </mesh>
	</geometry>
	<pose frame=''>0 0 0 0 -0 0</pose>
	<material>
	  <shader type='pixel'>
	    <normal_map>__default__</normal_map>
	  </shader>
	  <emissive>0 0 0 1</emissive>
	  <script>
	    <name>ModelPreview_20::leg_4::base_fixed_joint_lump__leg_4_visual_11_MATERIAL_</name>
	    <uri>__default__</uri>
	  </script>
	</material>
	<transparency>0</transparency>
	<cast_shadows>1</cast_shadows>
      </visual>
      <collision name='collision_0'>
	<laser_retro>0</laser_retro>
	<max_contacts>10</max_contacts>
	<pose frame=''>0 0 -0.08 0 -0 0</pose>
	<geometry>
	  <box>
	    <size>0.0889 0.074097 0.960287</size>
	  </box>
	</geometry>
	<surface>
	  <friction>
	    <ode>
	      <mu>1</mu>
	      <mu2>1</mu2>
	      <fdir1>0 0 0</fdir1>
	      <slip1>0</slip1>
	      <slip2>0</slip2>
	    </ode>
	    <torsional>
	      <coefficient>1</coefficient>
	      <patch_radius>0</patch_radius>
	      <surface_radius>0</surface_radius>
	      <use_patch_radius>1</use_patch_radius>
	      <ode>
		<slip>0</slip>
	      </ode>
	    </torsional>
	  </friction>
	  <bounce>
	    <restitution_coefficient>0</restitution_coefficient>
	    <threshold>1e+06</threshold>
	  </bounce>
	  <contact>
	    <collide_without_contact>0</collide_without_contact>
	    <collide_without_contact_bitmask>1</collide_without_contact_bitmask>
	    <collide_bitmask>1</collide_bitmask>
	    <ode>
	      <soft_cfm>0</soft_cfm>
	      <soft_erp>0.2</soft_erp>
	      <kp>1e+13</kp>
	      <kd>1</kd>
	      <max_vel>0.01</max_vel>
	      <min_depth>0</min_depth>
	    </ode>
	    <bullet>
	      <split_impulse>1</split_impulse>
	      <split_impulse_penetration_threshold>-0.01</split_impulse_penetration_threshold>
	      <soft_cfm>0</soft_cfm>
	      <soft_erp>0.2</soft_erp>
	      <kp>1e+13</kp>
	      <kd>1</kd>
	    </bullet>
	  </contact>
	</surface>
      </collision>
    </link>
    <link name='thruster_1'>
      <self_collide>0</self_collide>
      <inertial>
	<inertia>
	  <ixx>1</ixx>
	  <ixy>0</ixy>
	  <ixz>0</ixz>
	  <iyy>1</iyy>
	  <iyz>0</iyz>
	  <izz>1</izz>
	</inertia>
	<mass>.1</mass>
	<pose frame=''>0 0 0 0 -0 0</pose>
      </inertial>
      <enable_wind>0</enable_wind>
      <kinematic>0</kinematic>
      <gravity>1</gravity>
      <pose frame=''>-0.512312 -0 0.280913 0 -0 0</pose>
      <visual name='base_fixed_joint_lump__thruster_1_nozzle_visual_36'>
	<geometry>
	  <mesh>
	    <scale>1 1 1</scale>
	    <uri>model://lander/meshes/thruster_1_nozzle.stl</uri>
	  </mesh>
	</geometry>
	<pose frame=''>0 0 0 0 -0 0</pose>
	<material>
	  <shader type='pixel'>
	    <normal_map>__default__</normal_map>
	  </shader>
	  <script>
	    <name>ModelPreview_7::thruster_1::base_fixed_joint_lump__thruster_1_nozzle_visual_36_MATERIAL_</name>
	    <uri>__default__</uri>
	  </script>
	</material>
	<transparency>0</transparency>
	<cast_shadows>1</cast_shadows>
      </visual>
    </link>
    <link name='thruster_2'>
      <self_collide>0</self_collide>
      <inertial>
	<inertia>
	  <ixx>1</ixx>
	  <ixy>0</ixy>
	  <ixz>0</ixz>
	  <iyy>1</iyy>
	  <iyz>0</iyz>
	  <izz>1</izz>
	</inertia>
	<mass>.1</mass>
	<pose frame=''>0 0 0 0 -0 0</pose>
      </inertial>
      <enable_wind>0</enable_wind>
      <kinematic>0</kinematic>
      <gravity>1</gravity>
      <pose frame=''>0 -0.51261 0.287097 0 -0 0</pose>
      <visual name='base_fixed_joint_lump__thruster_2_nozzle_visual_39'>
	<geometry>
	  <mesh>
	    <scale>1 1 1</scale>
	    <uri>model://lander/meshes/thruster_2_nozzle.stl</uri>
	  </mesh>
	</geometry>
	<pose frame=''>0 0 0 0 -0 0</pose>
	<material>
	  <shader type='pixel'>
	    <normal_map>__default__</normal_map>
	  </shader>
	  <script>
	    <name>ModelPreview_7::thruster_2::base_fixed_joint_lump__thruster_2_nozzle_visual_39_MATERIAL_</name>
	    <uri>__default__</uri>
	  </script>
	</material>
	<transparency>0</transparency>
	<cast_shadows>1</cast_shadows>
      </visual>
    </link>
    <link name='thruster_3'>
      <self_collide>0</self_collide>
      <inertial>
	<inertia>
	  <ixx>1</ixx>
	  <ixy>0</ixy>
	  <ixz>0</ixz>
	  <iyy>1</iyy>
	  <iyz>0</iyz>
	  <izz>1</izz>
	</inertia>
	<mass>.1</mass>
	<pose frame=''>0 0 0 0 -0 0</pose>
      </inertial>
      <enable_wind>0</enable_wind>
      <kinematic>0</kinematic>
      <gravity>1</gravity>
      <pose frame=''>0.512693 0 0.285137 0 -0 0</pose>
      <visual name='base_fixed_joint_lump__thruster_3_nozzle_visual_42'>
	<geometry>
	  <mesh>
	    <scale>1 1 1</scale>
	    <uri>model://lander/meshes/thruster_3_nozzle.stl</uri>
	  </mesh>
	</geometry>
	<pose frame=''>0 0 0 0 -0 0</pose>
	<material>
	  <shader type='pixel'>
	    <normal_map>__default__</normal_map>
	  </shader>
	  <script>
	    <name>ModelPreview_7::thruster_3::base_fixed_joint_lump__thruster_3_nozzle_visual_42_MATERIAL_</name>
	    <uri>__default__</uri>
	  </script>
	</material>
	<transparency>0</transparency>
	<cast_shadows>1</cast_shadows>
      </visual>
    </link>
    <link name='thruster_4'>
      <self_collide>0</self_collide>
      <inertial>
	<inertia>
	  <ixx>1</ixx>
	  <ixy>0</ixy>
	  <ixz>0</ixz>
	  <iyy>1</iyy>
	  <iyz>0</iyz>
	  <izz>1</izz>
	</inertia>
	<mass>.1</mass>
	<pose frame=''>0 0 0 0 -0 0</pose>
      </inertial>
      <enable_wind>0</enable_wind>
      <kinematic>0</kinematic>
      <gravity>1</gravity>
      <pose frame=''>0 0.512953 0.289119 0 -0 0</pose>
      <visual name='base_fixed_joint_lump__thruster_4_nozzle_visual_45'>
	<geometry>
	  <mesh>
	    <scale>1 1 1</scale>
	    <uri>model://lander/meshes/thruster_4_nozzle.stl</uri>
	  </mesh>
	</geometry>
	<pose frame=''>0 0 0 0 -0 0</pose>
	<material>
	  <shader type='pixel'>
	    <normal_map>__default__</normal_map>
	  </shader>
	  <script>
	    <name>ModelPreview_7::thruster_4::base_fixed_joint_lump__thruster_4_nozzle_visual_45_MATERIAL_</name>
	    <uri>__default__</uri>
	  </script>
	</material>
	<transparency>0</transparency>
	<cast_shadows>1</cast_shadows>
      </visual>
    </link>

    <link name='lander/imu_link'>
      <pose>0 0 0.75 -0 -0 -0.09</pose>
      <inertial>
	<pose>0 0 0 0 -0 0</pose>
	<mass>0.015</mass>
	<inertia>
	  <ixx>1e-05</ixx>
	  <ixy>0</ixy>
	  <ixz>0</ixz>
	  <iyy>1e-05</iyy>
	  <iyz>0</iyz>
	  <izz>1e-05</izz>
	</inertia>
      </inertial>

      <!-- IMU -->
      <sensor name='lander_imu' type='imu'>
	<always_on>1</always_on>
	<imu/>
	<update_rate>100</update_rate>
	<visualize>true</visualize>
	<topic>imu</topic>
	<plugin filename="libgazebo_ros_imu_sensor.so" name="imu_plugin">
	  <topicName>imu</topicName>
	  <bodyName>lander/imu_link</bodyName>
	  <updateRateHZ>10.0</updateRateHZ>
	  <gaussianNoise>0.0</gaussianNoise>
	  <xyzOffset>0 0 0</xyzOffset>
	  <rpyOffset>0 0 0</rpyOffset>
	  <frameName>lander/imu_link</frameName>
	  <initialOrientationAsReference>false</initialOrientationAsReference>
	</plugin>
      </sensor>
      <self_collide>0</self_collide>
      <gravity>1</gravity>
    </link>
    <joint name='lander/imu_joint' type='fixed'>
      <parent>base</parent>
      <child>lander/imu_link</child>
      <pose>0 0 0 0 -0 0</pose>
    </joint>

    <!-- GPS -->
    <!-- <include> -->
    <!--   <uri>model://gps</uri> -->
    <!--   <pose>0 0 0.75 0 0 0</pose> -->
    <!--   <name>gps</name> -->
    <!-- </include> -->
    <!-- <joint name='gps_joint' type='fixed'> -->
    <!--   <child>gps::link</child> -->
    <!--   <parent>base</parent> -->
    <!-- </joint> -->

    <!-- airspeed sensor -->
    <!-- <link name='lander/airspeed_link'> -->
    <!--   <pose>0 0 0.75 0 -0 0</pose> -->
    <!--   <inertial> -->
    <!-- 	<pose>0 0 0 0 -0 0</pose> -->
    <!-- 	<mass>0.015</mass> -->
    <!-- 	<inertia> -->
    <!-- 	  <ixx>1e-05</ixx> -->
    <!-- 	  <ixy>0</ixy> -->
    <!-- 	  <ixz>0</ixz> -->
    <!-- 	  <iyy>1e-05</iyy> -->
    <!-- 	  <iyz>0</iyz> -->
    <!-- 	  <izz>1e-05</izz> -->
    <!-- 	</inertia> -->
    <!--   </inertial> -->
    <!--   <self_collide>0</self_collide> -->
    <!-- </link> -->
    <!-- <joint name='lander/airspeed_joint' type='revolute'> -->
    <!--   <parent>base</parent> -->
    <!--   <child>lander/airspeed_link</child> -->
    <!--   <pose>0 0 0 0 -0 0</pose> -->
    <!--   <axis> -->
    <!-- 	<xyz>1 0 0</xyz> -->
    <!-- 	<use_parent_model_frame>1</use_parent_model_frame> -->
    <!-- 	<limit> -->
    <!-- 	  <lower>0</lower> -->
    <!-- 	  <upper>0</upper> -->
    <!-- 	  <effort>0</effort> -->
    <!-- 	  <velocity>0</velocity> -->
    <!-- 	</limit> -->
    <!-- 	<dynamics> -->
    <!-- 	  <spring_reference>0</spring_reference> -->
    <!-- 	  <spring_stiffness>0</spring_stiffness> -->
    <!-- 	  <damping>0</damping> -->
    <!-- 	  <friction>0</friction> -->
    <!-- 	</dynamics> -->
    <!--   </axis> -->
    <!--   <physics> -->
    <!-- 	<ode> -->
    <!-- 	  <limit> -->
    <!-- 	    <cfm>0</cfm> -->
    <!-- 	    <erp>0.2</erp> -->
    <!-- 	  </limit> -->
    <!-- 	  <suspension> -->
    <!-- 	    <cfm>0</cfm> -->
    <!-- 	    <erp>0.2</erp> -->
    <!-- 	  </suspension> -->
    <!-- 	</ode> -->
    <!--   </physics> -->
    <!-- </joint> -->


    <joint name='actuator_1_inner__actuator_1_mount_front__ball' type='ball'>
      <parent>actuator_1_inner</parent>
      <child>actuator_1_mount_front</child>
      <pose frame=''>-0.02 0 0 0 -0 0</pose>
      <physics>
	<ode>
	  <limit>
	    <cfm>0</cfm>
	    <erp>0.2</erp>
	  </limit>
	  <suspension>
	    <cfm>0</cfm>
	    <erp>0.2</erp>
	  </suspension>
	</ode>
      </physics>
    </joint>
    <joint name='actuator_1_mount_back_JOINT_0' type='ball'>
      <parent>actuator_1_mount_back</parent>
      <child>actuator_1_outer</child>
      <pose frame=''>0.09 0 0.02 0 -0 0</pose>
      <physics>
	<ode>
	  <limit>
	    <cfm>0</cfm>
	    <erp>0.2</erp>
	  </limit>
	  <suspension>
	    <cfm>0</cfm>
	    <erp>0.2</erp>
	  </suspension>
	</ode>
      </physics>
    </joint>
    <joint name='actuator_1_mount_front__gimbal_actuator_mount_2__fixed' type='fixed'>
      <parent>actuator_1_mount_front</parent>
      <child>gimbal_actuator_mount_2</child>
      <pose frame=''>0 0 0 0 -0 0</pose>
      <physics>
	<ode>
	  <limit>
	    <cfm>0</cfm>
	    <erp>0.2</erp>
	  </limit>
	  <suspension>
	    <cfm>0</cfm>
	    <erp>0.2</erp>
	  </suspension>
	</ode>
      </physics>
    </joint>
    <joint name='actuator_1_outer__actuator_1_inner__prismatic' type='prismatic'>
      <parent>actuator_1_outer</parent>
      <child>actuator_1_inner</child>
      <pose frame=''>0 0 0 0 -0 0</pose>
      <axis>
	<xyz>-1 0 0</xyz>
	<use_parent_model_frame>0</use_parent_model_frame>
	<limit>
	  <lower>-0.0254</lower>
	  <upper>0.0762</upper>
	  <effort>900</effort>
	  <velocity>0.01</velocity>
	</limit>
	<dynamics>
	  <spring_reference>0</spring_reference>
	  <spring_stiffness>0</spring_stiffness>
	  <damping>0</damping>
	  <friction>0</friction>
	</dynamics>
      </axis>
      <physics>
	<ode>
	  <limit>
	    <cfm>0</cfm>
	    <erp>0.2</erp>
	  </limit>
	  <suspension>
	    <cfm>0</cfm>
	    <erp>0.2</erp>
	  </suspension>
	</ode>
      </physics>
    </joint>
    <joint name='actuator_2_inner__actuator_2_mount_front__ball' type='ball'>
      <parent>actuator_2_inner</parent>
      <child>actuator_2_mount_front</child>
      <pose frame=''>0.0175 0 0 0 -0 0</pose>
      <physics>
	<ode>
	  <limit>
	    <cfm>0</cfm>
	    <erp>0.2</erp>
	  </limit>
	  <suspension>
	    <cfm>0</cfm>
	    <erp>0.2</erp>
	  </suspension>
	</ode>
      </physics>
    </joint>
    <joint name='actuator_2_mount_back_JOINT_1' type='ball'>
      <parent>actuator_2_mount_back</parent>
      <child>actuator_2_outer</child>
      <pose frame=''>0.09 0 0.02 0 -0 0</pose>
      <physics>
	<ode>
	  <limit>
	    <cfm>0</cfm>
	    <erp>0.2</erp>
	  </limit>
	  <suspension>
	    <cfm>0</cfm>
	    <erp>0.2</erp>
	  </suspension>
	</ode>
      </physics>
    </joint>
    <joint name='actuator_2_mount_front__gimbal_actuator_mount_2__fixed' type='fixed'>
      <parent>actuator_2_mount_front</parent>
      <child>gimbal_actuator_mount_1</child>
      <pose frame=''>0 0 0 0 -0 0</pose>
      <physics>
	<ode>
	  <limit>
	    <cfm>0</cfm>
	    <erp>0.2</erp>
	  </limit>
	  <suspension>
	    <cfm>0</cfm>
	    <erp>0.2</erp>
	  </suspension>
	</ode>
      </physics>
    </joint>
    <joint name='actuator_2_outer__actuator_2_inner__prismatic' type='prismatic'>
      <parent>actuator_2_outer</parent>
      <child>actuator_2_inner</child>
      <pose frame=''>0 0 0 0 -0 0</pose>
      <axis>
	<xyz>-1 0 0</xyz>
	<use_parent_model_frame>0</use_parent_model_frame>
	<limit>
	  <lower>-0.0254</lower>
	  <upper>0.0762</upper>
	  <effort>900</effort>
	  <velocity>0.01</velocity>
	</limit>
	<dynamics>
	  <spring_reference>0</spring_reference>
	  <spring_stiffness>0</spring_stiffness>
	  <damping>0</damping>
	  <friction>0</friction>
	</dynamics>
      </axis>
      <physics>
	<ode>
	  <limit>
	    <cfm>0</cfm>
	    <erp>0.2</erp>
	  </limit>
	  <suspension>
	    <cfm>0</cfm>
	    <erp>0.2</erp>
	  </suspension>
	</ode>
      </physics>
    </joint>
    <joint name='base__actuator_1_mount_back__fixed' type='fixed'>
      <parent>base</parent>
      <child>actuator_1_mount_back</child>
      <pose frame=''>0 0 0 0 -0 0</pose>
      <physics>
	<ode>
	  <limit>
	    <cfm>0</cfm>
	    <erp>0.2</erp>
	  </limit>
	  <suspension>
	    <cfm>0</cfm>
	    <erp>0.2</erp>
	  </suspension>
	</ode>
      </physics>
    </joint>
    <joint name='base__actuator_2_mount_back__fixed' type='fixed'>
      <parent>base</parent>
      <child>actuator_2_mount_back</child>
      <pose frame=''>0 0 0 0 -0 0</pose>
      <physics>
	<ode>
	  <limit>
	    <cfm>0</cfm>
	    <erp>0.2</erp>
	  </limit>
	  <suspension>
	    <cfm>0</cfm>
	    <erp>0.2</erp>
	  </suspension>
	</ode>
      </physics>
    </joint>
    <joint name='base__gimbal_ring_outer__fixed' type='fixed'>
      <parent>base</parent>
      <child>gimbal_ring_outer</child>
      <pose frame=''>0 0 0 0 -0 0</pose>
      <physics>
	<ode>
	  <limit>
	    <cfm>0</cfm>
	    <erp>0.2</erp>
	  </limit>
	  <suspension>
	    <cfm>0</cfm>
	    <erp>0.2</erp>
	  </suspension>
	</ode>
      </physics>
    </joint>
    <joint name='base__leg_1__fixed' type='fixed'>
      <parent>base</parent>
      <child>leg_1</child>
      <pose frame=''>0 0 0 0 -0 0</pose>
      <physics>
	<ode>
	  <limit>
	    <cfm>0</cfm>
	    <erp>0.2</erp>
	  </limit>
	  <suspension>
	    <cfm>0</cfm>
	    <erp>0.2</erp>
	  </suspension>
	</ode>
      </physics>
    </joint>
    <joint name='base__leg_2__fixed' type='fixed'>
      <parent>base</parent>
      <child>leg_2</child>
      <pose frame=''>0 0 0 0 -0 0</pose>
      <physics>
	<ode>
	  <limit>
	    <cfm>0</cfm>
	    <erp>0.2</erp>
	  </limit>
	  <suspension>
	    <cfm>0</cfm>
	    <erp>0.2</erp>
	  </suspension>
	</ode>
      </physics>
    </joint>
    <joint name='base__leg_3__fixed' type='fixed'>
      <parent>base</parent>
      <child>leg_3</child>
      <pose frame=''>0 0 0 0 -0 0</pose>
      <physics>
	<ode>
	  <limit>
	    <cfm>0</cfm>
	    <erp>0.2</erp>
	  </limit>
	  <suspension>
	    <cfm>0</cfm>
	    <erp>0.2</erp>
	  </suspension>
	</ode>
      </physics>
    </joint>
    <joint name='base__leg_4__fixed' type='fixed'>
      <parent>base</parent>
      <child>leg_4</child>
      <pose frame=''>0 0 0 0 -0 0</pose>
      <physics>
	<ode>
	  <limit>
	    <cfm>0</cfm>
	    <erp>0.2</erp>
	  </limit>
	  <suspension>
	    <cfm>0</cfm>
	    <erp>0.2</erp>
	  </suspension>
	</ode>
      </physics>
    </joint>
    <joint name='base__thruster_1__fixed' type='fixed'>
      <parent>base</parent>
      <child>thruster_1</child>
      <pose frame=''>0 0 0 0 -0 0</pose>
      <physics>
	<ode>
	  <limit>
	    <cfm>0</cfm>
	    <erp>0.2</erp>
	  </limit>
	  <suspension>
	    <cfm>0</cfm>
	    <erp>0.2</erp>
	  </suspension>
	</ode>
      </physics>
    </joint>
    <joint name='base__thruster_2__fixed' type='fixed'>
      <parent>base</parent>
      <child>thruster_2</child>
      <pose frame=''>0 0 0 0 -0 0</pose>
      <physics>
	<ode>
	  <limit>
	    <cfm>0</cfm>
	    <erp>0.2</erp>
	  </limit>
	  <suspension>
	    <cfm>0</cfm>
	    <erp>0.2</erp>
	  </suspension>
	</ode>
      </physics>
    </joint>
    <joint name='base__thruster_3__fixed' type='fixed'>
      <parent>base</parent>
      <child>thruster_3</child>
      <pose frame=''>0 0 0 0 -0 0</pose>
      <physics>
	<ode>
	  <limit>
	    <cfm>0</cfm>
	    <erp>0.2</erp>
	  </limit>
	  <suspension>
	    <cfm>0</cfm>
	    <erp>0.2</erp>
	  </suspension>
	</ode>
      </physics>
    </joint>
    <joint name='base__thruster_4__fixed' type='fixed'>
      <parent>base</parent>
      <child>thruster_4</child>
      <pose frame=''>0 0 0 0 -0 0</pose>
      <physics>
	<ode>
	  <limit>
	    <cfm>0</cfm>
	    <erp>0.2</erp>
	  </limit>
	  <suspension>
	    <cfm>0</cfm>
	    <erp>0.2</erp>
	  </suspension>
	</ode>
      </physics>
    </joint>
    <joint name='gimbal_mid_rotate_1__gimbal_ring_inner__fixed' type='fixed'>
      <parent>gimbal_mid_rotate_1</parent>
      <child>gimbal_ring_inner</child>
      <pose frame=''>0 0 0 0 -0 0</pose>
      <physics>
	<ode>
	  <limit>
	    <cfm>0</cfm>
	    <erp>0.2</erp>
	  </limit>
	  <suspension>
	    <cfm>0</cfm>
	    <erp>0.2</erp>
	  </suspension>
	</ode>
      </physics>
    </joint>
    <joint name='gimbal_outer_rotate_1__gimbal_ring_mid__fixed' type='fixed'>
      <parent>gimbal_outer_rotate_1</parent>
      <child>gimbal_ring_mid</child>
      <pose frame=''>0 0 0 0 -0 0</pose>
      <physics>
	<ode>
	  <limit>
	    <cfm>0</cfm>
	    <erp>0.2</erp>
	  </limit>
	  <suspension>
	    <cfm>0</cfm>
	    <erp>0.2</erp>
	  </suspension>
	</ode>
      </physics>
    </joint>
    <joint name='gimbal_ring_inner__gimbal_actuator_mount_1__fixed' type='fixed'>
      <parent>gimbal_ring_inner</parent>
      <child>gimbal_actuator_mount_1</child>
      <pose frame=''>0 0 0 0 -0 0</pose>
      <physics>
	<ode>
	  <limit>
	    <cfm>0</cfm>
	    <erp>0.2</erp>
	  </limit>
	  <suspension>
	    <cfm>0</cfm>
	    <erp>0.2</erp>
	  </suspension>
	</ode>
      </physics>
    </joint>
    <joint name='gimbal_ring_inner__gimbal_actuator_mount_2__fixed' type='fixed'>
      <parent>gimbal_ring_inner</parent>
      <child>gimbal_actuator_mount_2</child>
      <pose frame=''>0 0 0 0 -0 0</pose>
      <physics>
	<ode>
	  <limit>
	    <cfm>0</cfm>
	    <erp>0.2</erp>
	  </limit>
	  <suspension>
	    <cfm>0</cfm>
	    <erp>0.2</erp>
	  </suspension>
	</ode>
      </physics>
    </joint>
    <joint name='gimbal_ring_mid__gimbal_mid_rotate_1__revolute' type='revolute'>
      <parent>gimbal_ring_mid</parent>
      <child>gimbal_mid_rotate_1</child>
      <pose frame=''>0 0 0 0 -0 0</pose>
      <axis>
	<xyz>0 1 0</xyz>
	<use_parent_model_frame>0</use_parent_model_frame>
	<limit>
	  <lower>-0.349066</lower>
	  <upper>0.349066</upper>
	  <effort>-1</effort>
	  <velocity>-1</velocity>
	</limit>
	<dynamics>
	  <spring_reference>0</spring_reference>
	  <spring_stiffness>0</spring_stiffness>
	  <damping>0</damping>
	  <friction>0</friction>
	</dynamics>
      </axis>
      <physics>
	<ode>
	  <limit>
	    <cfm>0</cfm>
	    <erp>0.2</erp>
	  </limit>
	  <suspension>
	    <cfm>0</cfm>
	    <erp>0.2</erp>
	  </suspension>
	</ode>
      </physics>
    </joint>
    <joint name='gimbal_ring_mid__gimbal_mid_rotate_2__fixed' type='fixed'>
      <parent>gimbal_ring_mid</parent>
      <child>gimbal_mid_rotate_2</child>
      <pose frame=''>0 0 0 0 -0 0</pose>
      <physics>
	<ode>
	  <limit>
	    <cfm>0</cfm>
	    <erp>0.2</erp>
	  </limit>
	  <suspension>
	    <cfm>0</cfm>
	    <erp>0.2</erp>
	  </suspension>
	</ode>
      </physics>
    </joint>
    <joint name='gimbal_ring_outer__gimbal_outer_rotate_1__revolute' type='revolute'>
      <parent>gimbal_ring_outer</parent>
      <child>gimbal_outer_rotate_1</child>
      <pose frame=''>0 0 0 0 -0 0</pose>
      <axis>
	<xyz>1 0 0</xyz>
	<use_parent_model_frame>0</use_parent_model_frame>
	<limit>
	  <lower>-0.349066</lower>
	  <upper>0.349066</upper>
	  <effort>-1</effort>
	  <velocity>-1</velocity>
	</limit>
	<dynamics>
	  <spring_reference>0</spring_reference>
	  <spring_stiffness>0</spring_stiffness>
	  <damping>0</damping>
	  <friction>0</friction>
	</dynamics>
      </axis>
      <physics>
	<ode>
	  <limit>
	    <cfm>0</cfm>
	    <erp>0.2</erp>
	  </limit>
	  <suspension>
	    <cfm>0</cfm>
	    <erp>0.2</erp>
	  </suspension>
	</ode>
      </physics>
    </joint>
    <joint name='gimbal_ring_outer__gimbal_outer_rotate_2__fixed' type='fixed'>
      <parent>gimbal_ring_outer</parent>
      <child>gimbal_outer_rotate_2</child>
      <pose frame=''>0 0 0 0 -0 0</pose>
      <physics>
	<ode>
	  <limit>
	    <cfm>0</cfm>
	    <erp>0.2</erp>
	  </limit>
	  <suspension>
	    <cfm>0</cfm>
	    <erp>0.2</erp>
	  </suspension>
	</ode>
      </physics>
    </joint>
    <static>0</static>
    <allow_auto_disable>1</allow_auto_disable>

    <!-- Plugins -->
    <plugin name="gazebo_interface" filename="libgazebo_interface.so">
      <thruster_1>thruster_1</thruster_1>
      <thruster_2>thruster_2</thruster_2>
      <thruster_3>thruster_3</thruster_3>
      <thruster_4>thruster_4</thruster_4>
      <actuator_1>actuator_1_inner</actuator_1>
      <actuator_2>actuator_2_inner</actuator_2>
      <engine>gimbal_ring_inner</engine>
    </plugin>

  </model>
</sdf>
